[2023-10-10T20:15:10.709+0000] {taskinstance.py:1157} INFO - Dependencies all met for dep_context=non-requeueable deps ti=<TaskInstance: airflow_exam.retrieve_raw_data scheduled__2023-10-10T20:13:00+00:00 [queued]>
[2023-10-10T20:15:10.715+0000] {taskinstance.py:1157} INFO - Dependencies all met for dep_context=requeueable deps ti=<TaskInstance: airflow_exam.retrieve_raw_data scheduled__2023-10-10T20:13:00+00:00 [queued]>
[2023-10-10T20:15:10.715+0000] {taskinstance.py:1359} INFO - Starting attempt 5 of 6
[2023-10-10T20:15:10.723+0000] {taskinstance.py:1380} INFO - Executing <Task(PythonOperator): retrieve_raw_data> on 2023-10-10 20:13:00+00:00
[2023-10-10T20:15:10.745+0000] {standard_task_runner.py:57} INFO - Started process 700 to run task
[2023-10-10T20:15:10.751+0000] {standard_task_runner.py:84} INFO - Running: ['***', 'tasks', 'run', '***_exam', 'retrieve_raw_data', 'scheduled__2023-10-10T20:13:00+00:00', '--job-id', '17', '--raw', '--subdir', 'DAGS_FOLDER/DAG.py', '--cfg-path', '/tmp/tmpxm58za12']
[2023-10-10T20:15:10.753+0000] {standard_task_runner.py:85} INFO - Job 17: Subtask retrieve_raw_data
[2023-10-10T20:15:10.776+0000] {warnings.py:109} WARNING - /home/***/.local/lib/python3.8/site-packages/***/settings.py:195: DeprecationWarning: The sql_alchemy_conn option in [core] has been moved to the sql_alchemy_conn option in [database] - the old setting has been used, but please update your config.
  SQL_ALCHEMY_CONN = conf.get("database", "SQL_ALCHEMY_CONN")

[2023-10-10T20:15:10.808+0000] {task_command.py:415} INFO - Running <TaskInstance: airflow_exam.retrieve_raw_data scheduled__2023-10-10T20:13:00+00:00 [running]> on host 11df5857e4c6
[2023-10-10T20:15:10.849+0000] {taskinstance.py:1660} INFO - Exporting env vars: AIRFLOW_CTX_DAG_OWNER='***' AIRFLOW_CTX_DAG_ID='***_exam' AIRFLOW_CTX_TASK_ID='retrieve_raw_data' AIRFLOW_CTX_EXECUTION_DATE='2023-10-10T20:13:00+00:00' AIRFLOW_CTX_TRY_NUMBER='5' AIRFLOW_CTX_DAG_RUN_ID='scheduled__2023-10-10T20:13:00+00:00'
[2023-10-10T20:15:10.852+0000] {taskinstance.py:1935} ERROR - Task failed with exception
Traceback (most recent call last):
  File "/home/airflow/.local/lib/python3.8/site-packages/airflow/operators/python.py", line 192, in execute
    return_value = self.execute_callable()
  File "/home/airflow/.local/lib/python3.8/site-packages/airflow/operators/python.py", line 209, in execute_callable
    return self.python_callable(*self.op_args, **self.op_kwargs)
  File "/opt/airflow/dags/data_ingestion.py", line 33, in ingest
    json.dump(data, file, indent=4)
UnboundLocalError: local variable 'data' referenced before assignment
[2023-10-10T20:15:10.858+0000] {taskinstance.py:1398} INFO - Marking task as UP_FOR_RETRY. dag_id=***_exam, task_id=retrieve_raw_data, execution_date=20231010T201300, start_date=20231010T201510, end_date=20231010T201510
[2023-10-10T20:15:10.863+0000] {standard_task_runner.py:104} ERROR - Failed to execute job 17 for task retrieve_raw_data (local variable 'data' referenced before assignment; 700)
[2023-10-10T20:15:10.887+0000] {local_task_job_runner.py:228} INFO - Task exited with return code 1
[2023-10-10T20:15:10.902+0000] {taskinstance.py:2776} INFO - 0 downstream tasks scheduled from follow-on schedule check
